# Исправление ошибки импорта datetime

## Проблема

При запуске автоматической проверки возникала ошибка:

```
UnboundLocalError: cannot access local variable 'datetime' where it is not associated with a value
File "C:\Users\Umar\Desktop\InstaChecker\project\cron\auto_checker.py", line 36
print(f"\n[AUTO-CHECK] {datetime.now()} - Starting automatic check...")
```

## Причина

В файле `project/cron/auto_checker.py` был конфликт между глобальным и локальными импортами из модуля `datetime`:

**Глобальный импорт** (строка 4):
```python
from datetime import datetime, timedelta
```

**Локальные импорты** внутри функций:
```python
from datetime import date  # Строка 175
from datetime import date, datetime  # Строка 189
```

Локальные импорты затеняли (shadowing) глобальный импорт `datetime`, из-за чего при попытке использовать `datetime.now()` на строке 36 возникала ошибка.

## Решение

### 1. Добавлен `date` в глобальный импорт

**Было**:
```python
from datetime import datetime, timedelta
```

**Стало**:
```python
from datetime import datetime, timedelta, date
```

### 2. Удалены локальные импорты

Удалены все локальные импорты `from datetime import ...` внутри функций, так как все необходимые классы уже импортированы глобально.

## Изменённые файлы

- ✅ `project/cron/auto_checker.py` - исправлен импорт datetime

## Проверка

После исправления:
```bash
# Больше нет конфликта импортов
grep "from datetime import" project/cron/auto_checker.py
# Вывод: from datetime import datetime, timedelta, date
```

## Дата исправления

16 октября 2025

